<?xml version="1.0"?>
<robot name="arm" xmlns:xacro="http://ros.org/wiki/xacro">

<xacro:property name="namespace" value="$(arg namespace)" />

<xacro:include filename="$(find rotors_description)/urdf/component_snippets.xacro" />

<xacro:arm_actuator_plugin_macro namespace="${namespace}"/>

<material name="blue">
    <color rgba="0 0 0.8 1"/>
</material>

<material name="green">
    <color rgba="0 0.8 0 1"/>
</material>

<material name="yellow">
    <color rgba="0.8 0.8 0 1"/>
</material>

<material name="black">
    <color rgba="0 0 0 1"/>
</material>

<material name="red">
    <color rgba="0.8 0 0 1"/>
</material>

<link name="world">
	<origin rpy="0 0 0" xyz="0 0 0"/>
</link>

<joint name="fixed_joint" type="fixed">
	<parent link="world"/>
	<child link="fixed_frame"/>
	<origin rpy="0 3.1416 0" xyz="0 0 1.1"/>
</joint>

<link name="fixed_frame">
	<origin rpy="0 0 0" xyz="0 0 0"/>
</link>

<joint name="fixed_joint_right" type="fixed">
	<parent link="fixed_frame"/>
	<child link="base_link_right"/>
	<origin rpy="0 0 0" xyz="0.11475 0 0.009"/>
</joint>

<link name="base_link_right">
	<visual>
		<origin rpy="0 0 0" xyz="0 0 0"/>
		<geometry>
		<mesh filename="package://rotors_description/meshes/arm/base_link.stl" scale="0.001 0.001 0.001"/>
		</geometry>
		<material name = "yellow"/>
	</visual>

    <collision>
      <origin xyz="0 0 39.875e-3" rpy="0 0 0"/>
      <geometry>
        <cylinder radius="26.05e-3" length="79.75e-3"/>
      </geometry>
    </collision>

    <inertial>
      <origin xyz="-2.2068363e-3 -9.1832072e-6 3.1955704e-3" rpy="-0.1729 0 1.5708"/>
      <mass value="0.396"/>
      <inertia
        ixx="3.1455842e-4" ixy="0.0" ixz="0.0"
        iyy="8.1358422e-4" iyz="0.0"
        izz="9.0317049e-4"/>
    </inertial>
</link>

 <joint name="Joint_shoulder_right" type="revolute">
 	<axis xyz="0 0 1"/>
 	<limit effort="1000.0" lower="-3.14" upper="+3.14" velocity="1"/>
	<parent link="base_link_right"/>
	<child link="Link_shoulder_right"/>
	<origin xyz="0 0 79.75e-3"/>
</joint>

<link name="Link_shoulder_right">
	<visual>
		<origin rpy="0 0 0" xyz="0 0 0"/>
		<geometry>
		<mesh filename="package://rotors_description/meshes/arm/j0.stl" scale="0.001 0.001 0.001"/>
		</geometry>
		<material name = "green"/>
	</visual>

    <collision>
      <origin xyz="0 0 42.572e-3" rpy="0 0 0"/>
      <geometry>
        <box size="41e-3 42.5e-3 85.144e-3"/>
      </geometry>
    </collision>

    <inertial>
      <origin xyz="-3.0707866e-6 9.0724801e-5 3.3368422e-3" rpy="1.5790 -0.0021 1.7506"/>
      <mass value="1.586"/>
      <inertia
        ixx="9.7058009e-4" ixy="0.0" ixz="0.0"
        iyy="5.8598889e-3" iyz="0.0"
        izz="6.2755829e-3"/>
    </inertial>
</link>

<joint name="fake_J1_A_right" type="revolute">
	<axis xyz="1 0 0"/>
 	<limit effort="1000.0" lower="0" upper="0.785" velocity="1"/>
	<parent link="Link_shoulder_right"/>
	<child link="fake_link_J1_right"/>
	<origin xyz="0 0 61.144e-3"/>
</joint>

<link name="fake_link_J1_right">
<!-- for a box: ixx = 0.083 * mass * (y*y + z*z) -->
<!-- for a box: ixy = 0 -->
<!-- for a box: ixz = 0 -->
<!-- for a box: iyy = 0.083 * mass * (x*x + z*z) -->
<!-- for a box: iyz = 0 -->
<!-- for a box: izz = 0.083 * mass * (x*x + y*y) -->
    <inertial>
      <origin xyz="0 0 0.024" rpy="0 0 0"/>
      <mass value="0.001"/>
      <inertia
        ixx="2e-7" ixy="0.0" ixz="0.0"
        iyy="2e-7" iyz="0.0"
        izz="2e-7"/>
    </inertial>
</link>

 <joint name="fake_J1_B_right" type="revolute">
 	<axis xyz="1 0 0"/>
 	<limit effort="1000.0" lower="0" upper="0.785" velocity="1"/>
	<parent link="fake_link_J1_right"/>
	<child link="Link_one_right"/>
	<origin xyz="0 0 0.048"/>
</joint>

<link name="Link_one_right">
	<visual>
		<origin rpy="0 0 0" xyz="0 0.0 0"/>
		<geometry>
		<mesh filename="package://rotors_description/meshes/arm/j1.stl" scale="0.001 0.001 0.001"/>
		</geometry>
		<material name = "black"/>
	</visual>

    <collision>
      <origin xyz="0 0 32.5e-3" rpy="0 0 0"/>
      <geometry>
        <box size="41e-3 42.5e-3 113e-3"/>
      </geometry>
    </collision>

    <inertial>
      <origin xyz="3.9623762e-4 5.2904518e-4 3.2046387e-2" rpy="-0.0193 -1.4555 -1.4511"/>
      <mass value="0.139"/>
      <inertia
        ixx="5.7544276e-5" ixy="0.0" ixz="0.0"
        iyy="1.7117076e-4" iyz="0.0"
        izz="1.7370141e-4"/>
    </inertial>
</link>

<joint name="fake_J2_A_right" type="revolute">
	<axis xyz="1 0 0"/>
 	<limit effort="1000.0" lower="-0.785" upper="0" velocity="1"/>
	<parent link="Link_one_right"/>
	<child link="fake_link_J2_right"/>
	<origin xyz="0 0 0.065"/>
</joint>

<link name="fake_link_J2_right">
    <inertial>
      <origin xyz="0 0 0.024" rpy="0 0 0"/>
      <mass value="0.001"/>
      <inertia
        ixx="2e-7" ixy="0.0" ixz="0.0"
        iyy="2e-7" iyz="0.0"
        izz="2e-7"/>
    </inertial>
</link>

<joint name="fake_J2_B_right" type="revolute">
	<axis xyz="1 0 0"/>
 	<limit effort="1000.0" lower="-0.785" upper="0" velocity="1"/>
	<parent link="fake_link_J2_right"/>
	<child link="Link_two_right"/>
	<origin xyz="0 0 0.048"/>
</joint>

<link name="Link_two_right">
	<visual>
		<origin rpy="0 0 0" xyz="0 0 0"/>
		<geometry>
		<mesh filename="package://rotors_description/meshes/arm/j2.stl" scale="0.001 0.001 0.001"/>
		</geometry>
		<material name = "red"/>
	</visual>

    <collision>
      <origin xyz="0 0 45e-3" rpy="0 0 0"/>
      <geometry>
        <box size="41e-3 42.5e-3 138e-3"/>
      </geometry>
    </collision>

    <inertial>
      <origin xyz="5.1358654e-4 1.4848633e-3 4.0707125e-2" rpy="3.0686 -1.5089 1.6549"/>
      <mass value="0.154"/>
      <inertia
        ixx="9.2363919e-5" ixy="0.0" ixz="0.0"
        iyy="2.7365867e-4" iyz="0.0"
        izz="2.7990892e-4"/>
    </inertial>
</link>

<joint name="fake_J3_A_right" type="revolute">
	<axis xyz="1 0 0"/>
 	<limit effort="1000.0" lower="0" upper="0.785" velocity="1"/>
	<parent link="Link_two_right"/>
	<child link="fake_link_J3_right"/>
	<origin xyz="0 0 0.090"/>
</joint>

<link name="fake_link_J3_right">
	<inertial>
      <origin xyz="0 0 0.024" rpy="0 0 0"/>
      <mass value="0.001"/>
      <inertia
        ixx="2e-7" ixy="0.0" ixz="0.0"
        iyy="2e-7" iyz="0.0"
        izz="2e-7"/>
    </inertial>
</link>

<joint name="fake_J3_B_right" type="revolute">
	<axis xyz="1 0 0"/>
 	<limit effort="1000.0" lower="0" upper="0.785" velocity="1"/>
	<parent link="fake_link_J3_right"/>
	<child link="Link_three_right"/>
	<origin xyz="0 0 0.048"/>
</joint>

<link name="Link_three_right">
	<visual>
		<origin rpy="0 0 0" xyz="0 0 0"/>
		<geometry>
		<mesh filename="package://rotors_description/meshes/arm/j3.stl" scale="0.001 0.001 0.001"/>
		</geometry>
		<material name = "blue"/>
	</visual>

    <collision>
      <origin xyz="0 0 51.1e-3" rpy="0 0 0"/>
      <geometry>
        <box size="41e-3 42.5e-3 150.2e-3"/>
      </geometry>
    </collision>

    <inertial>
      <origin xyz="1.0689991e-4 4.5539723e-3 5.6348105e-2" rpy="0.0503 -1.4936 -1.6299"/>
      <mass value="0.207"/>
      <inertia
        ixx="8.4188171e-5" ixy="0.0" ixz="0.0"
        iyy="3.4408597e-4" iyz="0.0"
        izz="3.6490830e-4"/>
    </inertial>
</link>
 
<joint name="Joint_wrist_right" type="revolute">
	<axis xyz="0 0 1"/>
 	<limit effort="1000.0" lower="-3.14" upper="3.14" velocity="1"/>
	<parent link="Link_three_right"/>
	<child link="Link_hand_right"/>
	<origin xyz="0 0 0.1262"/>
</joint>

<link name="Link_hand_right">
	<visual>
		<origin rpy="0 0 0 " xyz="0 0 0"/>
		<geometry>
    <mesh filename="package://rotors_description/meshes/arm/hand_right.stl" scale="0.001 0.001 0.001"/>
    </geometry>
		<material name = "black"/>
	</visual>

    <collision>
      <origin xyz="0 0 102.556e-3" rpy="0 0 0"/>
      <geometry>
        <box size="41e-3 54e-3 205.122e-3"/>
      </geometry>
    </collision>

    <inertial>
      <origin xyz="-5.1914952e-3 9.4338844e-4 8.4791871e-2" rpy="2.7807 -1.4896 1.8174"/>
      <mass value="0.505"/>
      <inertia
        ixx="3.2734333e-4" ixy="0.0" ixz="0.0"
        iyy="1.1324016e-3" iyz="0.0"
        izz="1.3591446e-3"/>
    </inertial>
</link>
 
<joint name="fixed_joint_left" type="fixed">
	<parent link="fixed_frame"/>
	<child link="base_link_left"/>
	<origin rpy="0 0 0" xyz="-0.11475 0 0.009"/>
</joint>

<link name="base_link_left">
	<visual>
		<origin rpy="0 0 0" xyz="0 0 0"/>
		<geometry>
		<mesh filename="package://rotors_description/meshes/arm/base_link.stl" scale="0.001 0.001 0.001"/>
		</geometry>
		<material name = "yellow"/>
	</visual>

    <collision>
      <origin xyz="0 0 0" rpy="0 0 0"/>
      <geometry>
        <box size="0.1 0.1 0.1"/>
      </geometry>
    </collision>

    <inertial>
      <origin xyz="-2.2068363e-3 -9.1832072e-6 3.1955704e-3" rpy="-0.1729 0 1.5708"/>
      <mass value="0.396"/>
      <inertia
        ixx="3.1455842e-4" ixy="0.0" ixz="0.0"
        iyy="8.1358422e-4" iyz="0.0"
        izz="9.0317049e-4"/>
    </inertial>
</link>

 <joint name="Joint_shoulder_left" type="revolute">
 	<axis xyz="0 0 1"/>
 	<limit effort="1000.0" lower="-3.14" upper="+3.14" velocity="1"/>
	<parent link="base_link_left"/>
	<child link="Link_shoulder_left"/>
	<origin xyz="0 0 79.75e-3"/>
</joint>

<link name="Link_shoulder_left">
	<visual>
		<origin rpy="0 0 0" xyz="0 0 0"/>
		<geometry>
		<mesh filename="package://rotors_description/meshes/arm/j0.stl" scale="0.001 0.001 0.001"/>
		</geometry>
		<material name = "green"/>
	</visual>

    <collision>
      <origin xyz="0 0 42.572e-3" rpy="0 0 0"/>
      <geometry>
        <box size="41e-3 42.5e-3 85.144e-3"/>
      </geometry>
    </collision>

    <inertial>
      <origin xyz="-3.0707866e-6 9.0724801e-5 3.3368422e-3" rpy="1.5790 -0.0021 1.7506"/>
      <mass value="1.586"/>
      <inertia
        ixx="9.7058009e-4" ixy="0.0" ixz="0.0"
        iyy="5.8598889e-3" iyz="0.0"
        izz="6.2755829e-3"/>
    </inertial>
</link>

<joint name="fake_J1_A_left" type="revolute">
	<axis xyz="1 0 0"/>
 	<limit effort="1000.0" lower="0" upper="0.785" velocity="1"/>
	<parent link="Link_shoulder_left"/>
	<child link="fake_link_J1_left"/>
	<origin xyz="0 0 61.144e-3"/>
</joint>

<link name="fake_link_J1_left">
<!-- for a box: ixx = 0.083 * mass * (y*y + z*z) -->
<!-- for a box: ixy = 0 -->
<!-- for a box: ixz = 0 -->
<!-- for a box: iyy = 0.083 * mass * (x*x + z*z) -->
<!-- for a box: iyz = 0 -->
<!-- for a box: izz = 0.083 * mass * (x*x + y*y) -->
    <inertial>
      <origin xyz="0 0 0.024" rpy="0 0 0"/>
      <mass value="0.001"/>
      <inertia
        ixx="2e-7" ixy="0.0" ixz="0.0"
        iyy="2e-7" iyz="0.0"
        izz="2e-7"/>
    </inertial>
</link>

 <joint name="fake_J1_B_left" type="revolute">
 	<axis xyz="1 0 0"/>
 	<limit effort="1000.0" lower="0" upper="0.785" velocity="1"/>
	<parent link="fake_link_J1_left"/>
	<child link="Link_one_left"/>
	<origin xyz="0 0 0.048"/>
</joint>

<link name="Link_one_left">
	<visual>
		<origin rpy="0 0 0" xyz="0 0 0"/>
		<geometry>
		<mesh filename="package://rotors_description/meshes/arm/j1.stl" scale="0.001 0.001 0.001"/>
		</geometry>
		<material name = "black"/>
	</visual>

    <collision>
      <origin xyz="0 0 32.5e-3" rpy="0 0 0"/>
      <geometry>
        <box size="41e-3 42.5e-3 113e-3"/>
      </geometry>
    </collision>

    <inertial>
      <origin xyz="3.9623762e-4 5.2904518e-4 3.2046387e-2" rpy="-0.0193 -1.4555 -1.4511"/>
      <mass value="0.139"/>
      <inertia
        ixx="5.7544276e-5" ixy="0.0" ixz="0.0"
        iyy="1.7117076e-4" iyz="0.0"
        izz="1.7370141e-4"/>
    </inertial>
</link>

<joint name="fake_J2_A_left" type="revolute">
	<axis xyz="1 0 0"/>
 	<limit effort="1000.0" lower="-0.785" upper="0" velocity="1"/>
	<parent link="Link_one_left"/>
	<child link="fake_link_J2_left"/>
	<origin xyz="0 0 0.065"/>
</joint>

<link name="fake_link_J2_left">
	    <inertial>
      <origin xyz="0 0 0.024" rpy="0 0 0"/>
      <mass value="0.001"/>
      <inertia
        ixx="2e-7" ixy="0.0" ixz="0.0"
        iyy="2e-7" iyz="0.0"
        izz="2e-7"/>
    </inertial>
</link>

<joint name="fake_J2_B_left" type="revolute">
	<axis xyz="1 0 0"/>
 	<limit effort="1000.0" lower="-0.785" upper="0" velocity="1"/>
	<parent link="fake_link_J2_left"/>
	<child link="Link_two_left"/>
	<origin xyz="0 0 0.048"/>
</joint>

<link name="Link_two_left">
	<visual>
		<origin rpy="0 0 0" xyz="0 0 0"/>
		<geometry>
		<mesh filename="package://rotors_description/meshes/arm/j2.stl" scale="0.001 0.001 0.001"/>
		</geometry>
		<material name = "red"/>
	</visual>

    <collision>
      <origin xyz="0 0 45e-3" rpy="0 0 0"/>
      <geometry>
        <box size="41e-3 42.5e-3 138e-3"/>
      </geometry>
    </collision>

    <inertial>
      <origin xyz="5.1358654e-4 1.4848633e-3 4.0707125e-2" rpy="3.0686 -1.5089 1.6549"/>
      <mass value="0.154"/>
      <inertia
        ixx="9.2363919e-5" ixy="0.0" ixz="0.0"
        iyy="2.7365867e-4" iyz="0.0"
        izz="2.7990892e-4"/>
    </inertial>
</link>

<joint name="fake_J3_A_left" type="revolute">
	<axis xyz="1 0 0"/>
 	<limit effort="1000.0" lower="0" upper="0.785" velocity="1"/>
	<parent link="Link_two_left"/>
	<child link="fake_link_J3_left"/>
	<origin xyz="0 0 0.090"/>
</joint>

<link name="fake_link_J3_left">
	<inertial>
      <origin xyz="0 0 0.024" rpy="0 0 0"/>
      <mass value="0.001"/>
      <inertia
        ixx="2e-7" ixy="0.0" ixz="0.0"
        iyy="2e-7" iyz="0.0"
        izz="2e-7"/>
    </inertial>
</link>

<joint name="fake_J3_B_left" type="revolute">
	<axis xyz="1 0 0"/>
 	<limit effort="1000.0" lower="0" upper="0.785" velocity="1"/>
	<parent link="fake_link_J3_left"/>
	<child link="Link_three_left"/>
	<origin xyz="0 0 0.048"/>
</joint>

<link name="Link_three_left">
	<visual>
		<origin rpy="0 0 0" xyz="0 0 0"/>
		<geometry>
		<mesh filename="package://rotors_description/meshes/arm/j3.stl" scale="0.001 0.001 0.001"/>
		</geometry>
		<material name = "blue"/>
	</visual>

    <collision>
      <origin xyz="0 0 51.1e-3" rpy="0 0 0"/>
      <geometry>
        <box size="41e-3 42.5e-3 150.2e-3"/>
      </geometry>
    </collision>

    <inertial>
      <origin xyz="1.0689991e-4 4.5539723e-3 5.6348105e-2" rpy="0.0503 -1.4936 -1.6299"/>
      <mass value="0.207"/>
      <inertia
        ixx="8.4188171e-5" ixy="0.0" ixz="0.0"
        iyy="3.4408597e-4" iyz="0.0"
        izz="3.6490830e-4"/>
    </inertial>
</link>
 
<joint name="Joint_wrist_left" type="revolute">
	<axis xyz="0 0 1"/>
 	<limit effort="1000.0" lower="-3.14" upper="3.14" velocity="1"/>
	<parent link="Link_three_left"/>
	<child link="Link_hand_left"/>
	<origin xyz="0 0 0.1262"/>
</joint>

<link name="Link_hand_left">
	<visual>
		<origin rpy="0 0 0 " xyz="0 0 0"/>
		<geometry>
    <mesh filename="package://rotors_description/meshes/arm/hand_left.stl" scale="0.001 0.001 0.001"/>
    </geometry>
		<material name = "black"/>
	</visual>

    <collision>
      <origin xyz="0 0 102.556e-3" rpy="0 0 0"/>
      <geometry>
        <box size="41e-3 54e-3 205.122e-3"/>
      </geometry>
    </collision>

    <inertial>
      <origin xyz="-5.1914952e-3 9.4338844e-4 8.4791871e-2" rpy="2.7807 -1.4896 1.8174"/>
      <mass value="0.505"/>
      <inertia
        ixx="3.2734333e-4" ixy="0.0" ixz="0.0"
        iyy="1.1324016e-3" iyz="0.0"
        izz="1.3591446e-3"/>
    </inertial>
</link>

</robot>