<?xml version="1.0"?>
<!--
BSD 3-Clause License

Copyright (c) 2022, NMMI
All rights reserved.

Redistribution and use in source and binary forms, with or without
modification, are permitted provided that the following conditions are met:

1. Redistributions of source code must retain the above copyright notice, this
   list of conditions and the following disclaimer.

2. Redistributions in binary form must reproduce the above copyright notice,
   this list of conditions and the following disclaimer in the documentation
   and/or other materials provided with the distribution.

3. Neither the name of the copyright holder nor the names of its
   contributors may be used to endorse or promote products derived from
   this software without specific prior written permission.

THIS SOFTWARE IS PROVIDED BY THE COPYRIGHT HOLDERS AND CONTRIBUTORS "AS IS"
AND ANY EXPRESS OR IMPLIED WARRANTIES, INCLUDING, BUT NOT LIMITED TO, THE
IMPLIED WARRANTIES OF MERCHANTABILITY AND FITNESS FOR A PARTICULAR PURPOSE ARE
DISCLAIMED. IN NO EVENT SHALL THE COPYRIGHT HOLDER OR CONTRIBUTORS BE LIABLE
FOR ANY DIRECT, INDIRECT, INCIDENTAL, SPECIAL, EXEMPLARY, OR CONSEQUENTIAL
DAMAGES (INCLUDING, BUT NOT LIMITED TO, PROCUREMENT OF SUBSTITUTE GOODS OR
SERVICES; LOSS OF USE, DATA, OR PROFITS; OR BUSINESS INTERRUPTION) HOWEVER
CAUSED AND ON ANY THEORY OF LIABILITY, WHETHER IN CONTRACT, STRICT LIABILITY,
OR TORT (INCLUDING NEGLIGENCE OR OTHERWISE) ARISING IN ANY WAY OUT OF THE USE
OF THIS SOFTWARE, EVEN IF ADVISED OF THE POSSIBILITY OF SUCH DAMAGE.
-->
<robot xmlns:xacro="http://ros.org/wiki/xacro">

  <xacro:macro name="arm_base_macro" params="robot_namespace parent_link">


    <gazebo>
      <plugin name="gazebo_ros_control" filename="libgazebo_ros_control.so">
        <robotNamespace>${robot_namespace}</robotNamespace>
      </plugin>
    </gazebo>

    <xacro:property name="joint_radius" value="24e-3" />

    <xacro:property name="friction" value="1e-5" />
    <xacro:property name="damping" value="5e-3" />

    <xacro:property name="PI" value="3.1415926535897931"/>


    <joint name="fixed_joint_right" type="fixed">
      <parent link="${parent_link}"/>
      <child link="base_link_right"/>
      <origin rpy="0 ${PI} 0" xyz="-0.11475 0 0.009"/>
    </joint>

    <link name="base_link_right">
      <visual>
        <origin rpy="0 0 0" xyz="0 0 0"/>
        <geometry>
          <mesh filename="package://aerial_ego_simulation/meshes/arm/base_link.stl" scale="0.001 0.001 0.001"/>
        </geometry>
      </visual>

      <collision>
        <origin xyz="0 0 39.875e-3" rpy="0 0 0"/>
        <geometry>
          <cylinder radius="26.05e-3" length="79.75e-3"/>
        </geometry>
      </collision>

      <inertial>
        <origin xyz="-2.2068363e-3 -9.1832072e-6 3.1955704e-3" rpy="-0.1729 0 1.5708"/>
        <mass value="0.396"/>
        <inertia ixx="3.1455842e-4" ixy="0.0" ixz="0.0" iyy="8.1358422e-4" iyz="0.0" izz="9.0317049e-4"/>
      </inertial>
    </link>

    <joint name="Joint_shoulder_right" type="revolute">
      <axis xyz="0 0 1"/>
      <limit effort="1000.0" lower="-3.14" upper="+3.14" velocity="1"/>
      <parent link="base_link_right"/>
      <child link="Link_shoulder_right"/>
      <origin xyz="0 0 79.75e-3"/>
      <dynamics damping="${damping}" friction="${friction}"/>
    </joint>

    <link name="Link_shoulder_right">
      <visual>
        <origin rpy="0 0 0" xyz="0 0 0"/>
        <geometry>
          <mesh filename="package://aerial_ego_simulation/meshes/arm/j0.stl" scale="0.001 0.001 0.001"/>
        </geometry>
      </visual>

      <collision>
        <origin xyz="0 0 42.572e-3" rpy="0 0 0"/>
        <geometry>
          <box size="41e-3 42.5e-3 85.144e-3"/>
        </geometry>
      </collision>

      <inertial>
        <origin xyz="-3.0707866e-6 9.0724801e-5 3.3368422e-3" rpy="1.5790 -0.0021 1.7506"/>
        <mass value="1.586"/>
        <inertia ixx="9.7058009e-4" ixy="0.0" ixz="0.0" iyy="5.8598889e-3" iyz="0.0" izz="6.2755829e-3"/>
      </inertial>
    </link>

    <joint name="Joint_1_right" type="revolute">
      <axis xyz="1 0 0"/>
      <limit effort="1000.0" lower="0" upper="1.571" velocity="1"/>
      <parent link="Link_shoulder_right"/>
      <child link="Link_one_right"/>
      <origin xyz="0 0 85.144e-3"/>
      <dynamics damping="${damping}" friction="${friction}"/>
    </joint>


    <link name="Link_one_right">
      <visual>
        <origin rpy="0 0 0" xyz="0 0 24e-3"/>
        <geometry>
          <mesh filename="package://aerial_ego_simulation/meshes/arm/j1.stl" scale="0.001 0.001 0.001"/>
        </geometry>
      </visual>

      <collision>
        <origin xyz="0 0 56.5e-3" rpy="0 0 0"/>
        <geometry>
          <box size="41e-3 42.5e-3 113e-3"/>
        </geometry>
      </collision>

      <inertial>
        <origin xyz="3.9623762e-4 5.2904518e-4 5.6046387e-2" rpy="-0.0193 -1.4555 -1.4511"/>
        <mass value="0.139"/>
        <inertia ixx="5.7544276e-5" ixy="0.0" ixz="0.0" iyy="1.7117076e-4" iyz="0.0" izz="1.7370141e-4"/>
      </inertial>
    </link>

    <joint name="Joint_2_right" type="revolute">
      <axis xyz="1 0 0"/>
      <limit effort="1000.0" lower="-1.571" upper="0" velocity="1"/>
      <parent link="Link_one_right"/>
      <child link="Link_two_right"/>
      <origin xyz="0 0 0.113"/>
      <dynamics damping="${damping}" friction="${friction}"/>
    </joint>


    <link name="Link_two_right">
      <visual>
        <origin rpy="0 0 0" xyz="0 0 24e-3"/>
        <geometry>
          <mesh filename="package://aerial_ego_simulation/meshes/arm/j2.stl" scale="0.001 0.001 0.001"/>
        </geometry>
      </visual>

      <collision>
        <origin xyz="0 0 69e-3" rpy="0 0 0"/>
        <geometry>
          <box size="41e-3 42.5e-3 138e-3"/>
        </geometry>
      </collision>

      <inertial>
        <origin xyz="5.1358654e-4 1.4848633e-3 6.4707125e-2" rpy="3.0686 -1.5089 1.6549"/>
        <mass value="0.154"/>
        <inertia ixx="9.2363919e-5" ixy="0.0" ixz="0.0" iyy="2.7365867e-4" iyz="0.0" izz="2.7990892e-4"/>
      </inertial>
    </link>

    <joint name="Joint_3_right" type="revolute">
      <axis xyz="1 0 0"/>
      <limit effort="1000.0" lower="0" upper="1.571" velocity="1"/>
      <parent link="Link_two_right"/>
      <child link="Link_three_right"/>
      <origin xyz="0 0 0.138"/>
      <dynamics damping="${damping}" friction="${friction}"/>
    </joint>


    <link name="Link_three_right">
      <visual>
        <origin rpy="0 0 0" xyz="0 0 24e-3"/>
        <geometry>
          <mesh filename="package://aerial_ego_simulation/meshes/arm/j3.stl" scale="0.001 0.001 0.001"/>
        </geometry>
      </visual>

      <collision>
        <origin xyz="0 0 75.1e-3" rpy="0 0 0"/>
        <geometry>
          <box size="41e-3 42.5e-3 150.2e-3"/>
        </geometry>
      </collision>

      <inertial>
        <origin xyz="1.0689991e-4 4.5539723e-3 8.0348105e-2" rpy="0.0503 -1.4936 -1.6299"/>
        <mass value="0.207"/>
        <inertia ixx="8.4188171e-5" ixy="0.0" ixz="0.0" iyy="3.4408597e-4" iyz="0.0" izz="3.6490830e-4"/>
      </inertial>
    </link>

    <joint name="Joint_wrist_right" type="revolute">
      <axis xyz="0 0 1"/>
      <limit effort="1000.0" lower="-3.14" upper="3.14" velocity="1"/>
      <parent link="Link_three_right"/>
      <child link="Link_hand_right"/>
      <origin xyz="0 0 0.1502" rpy="0 0 ${pi/2}"/>
      <dynamics damping="${damping}" friction="${friction}"/>
    </joint>

    <link name="Link_hand_right">
      <visual>
        <origin rpy="0 0 0 " xyz="0 0 0"/>
        <geometry>
          <mesh filename="package://aerial_ego_simulation/meshes/arm/hand_right.stl" scale="0.001 0.001 0.001"/>
        </geometry>
      </visual>

      <collision>

        <surface>
          <!-- <contact>
              <ode>
                <max_vel>10</max_vel>
                <min_depth>0.001</min_depth>
              </ode>
            </contact>         -->

          <friction>
            <ode>
              <mu>5</mu>
              <mu2>5</mu2>
              <kp value="10000000.0" />
              <kd value="1.0" />
            </ode>
          </friction>
          <!-- <soft_contact>
          <dart>
            <bone_attachment>100
            </bone_attachment>
            <stiffness>100
            </stiffness>
            <damping>10
            </damping>
          </dart>
        </soft_contact> -->
        </surface>

        <origin xyz="0 0 102.556e-3" rpy="0 0 0"/>
        <geometry>
          <box size="80e-3 36e-3 205.122e-3"/>
        </geometry>
      </collision>

      <inertial>
        <origin xyz="-5.1914952e-3 9.4338844e-4 8.4791871e-2" rpy="2.7807 -1.4896 1.8174"/>
        <mass value="0.505"/>
        <inertia ixx="3.2734333e-4" ixy="0.0" ixz="0.0" iyy="1.1324016e-3" iyz="0.0" izz="1.3591446e-3"/>
      </inertial>
    </link>

    <joint name="fixed_joint_left" type="fixed">
      <parent link="${parent_link}"/>
      <child link="base_link_left"/>
      <origin rpy="0 3.1416 0" xyz="0.11475 0 0.009"/>
    </joint>

    <link name="base_link_left">
      <visual>
        <origin rpy="0 0 0" xyz="0 0 0"/>
        <geometry>
          <mesh filename="package://aerial_ego_simulation/meshes/arm/base_link.stl" scale="0.001 0.001 0.001"/>
        </geometry>
      </visual>

      <collision>
        <origin xyz="0 0 39.875e-3" rpy="0 0 0"/>
        <geometry>
          <cylinder radius="26.05e-3" length="79.75e-3"/>
        </geometry>
      </collision>

      <inertial>
        <origin xyz="-2.2068363e-3 -9.1832072e-6 3.1955704e-3" rpy="-0.1729 0 1.5708"/>
        <mass value="0.396"/>
        <inertia ixx="3.1455842e-4" ixy="0.0" ixz="0.0" iyy="8.1358422e-4" iyz="0.0" izz="9.0317049e-4"/>
      </inertial>
    </link>

    <joint name="Joint_shoulder_left" type="revolute">
      <axis xyz="0 0 1"/>
      <limit effort="1000.0" lower="-3.14" upper="+3.14" velocity="1"/>
      <parent link="base_link_left"/>
      <child link="Link_shoulder_left"/>
      <origin xyz="0 0 79.75e-3"/>
      <dynamics damping="${damping}" friction="${friction}"/>

    </joint>

    <link name="Link_shoulder_left">
      <visual>
        <origin rpy="0 0 0" xyz="0 0 0"/>
        <geometry>
          <mesh filename="package://aerial_ego_simulation/meshes/arm/j0.stl" scale="0.001 0.001 0.001"/>
        </geometry>
      </visual>

      <collision>
        <origin xyz="0 0 42.572e-3" rpy="0 0 0"/>
        <geometry>
          <box size="41e-3 42.5e-3 85.144e-3"/>
        </geometry>
      </collision>

      <inertial>
        <origin xyz="-3.0707866e-6 9.0724801e-5 3.3368422e-3" rpy="1.5790 -0.0021 1.7506"/>
        <mass value="1.586"/>
        <inertia ixx="9.7058009e-4" ixy="0.0" ixz="0.0" iyy="5.8598889e-3" iyz="0.0" izz="6.2755829e-3"/>
      </inertial>
    </link>

    <joint name="Joint_1_left" type="revolute">
      <axis xyz="1 0 0"/>
      <limit effort="1000.0" lower="0" upper="1.571" velocity="1"/>
      <parent link="Link_shoulder_left"/>
      <child link="Link_one_left"/>
      <origin xyz="0 0 85.144e-3"/>
      <dynamics damping="${damping}" friction="${friction}"/>

    </joint>

    <link name="Link_one_left">
      <visual>
        <origin rpy="0 0 0" xyz="0 0 24e-3"/>
        <geometry>
          <mesh filename="package://aerial_ego_simulation/meshes/arm/j1.stl" scale="0.001 0.001 0.001"/>
        </geometry>
      </visual>

      <collision>
        <origin xyz="0 0 56.5e-3" rpy="0 0 0"/>
        <geometry>
          <box size="41e-3 42.5e-3 113e-3"/>
        </geometry>
      </collision>

      <inertial>
        <origin xyz="3.9623762e-4 5.2904518e-4 5.6046387e-2" rpy="-0.0193 -1.4555 -1.4511"/>
        <mass value="0.139"/>
        <inertia ixx="5.7544276e-5" ixy="0.0" ixz="0.0" iyy="1.7117076e-4" iyz="0.0" izz="1.7370141e-4"/>
      </inertial>
    </link>

    <joint name="Joint_2_left" type="revolute">
      <axis xyz="1 0 0"/>
      <limit effort="1000.0" lower="-1.571" upper="0" velocity="1"/>
      <parent link="Link_one_left"/>
      <child link="Link_two_left"/>
      <origin xyz="0 0 0.113"/>
      <dynamics damping="${damping}" friction="${friction}"/>

    </joint>


    <link name="Link_two_left">
      <visual>
        <origin rpy="0 0 0" xyz="0 0 24e-3"/>
        <geometry>
          <mesh filename="package://aerial_ego_simulation/meshes/arm/j2.stl" scale="0.001 0.001 0.001"/>
        </geometry>
      </visual>

      <collision>
        <origin xyz="0 0 69e-3" rpy="0 0 0"/>
        <geometry>
          <box size="41e-3 42.5e-3 138e-3"/>
        </geometry>
      </collision>

      <inertial>
        <origin xyz="5.1358654e-4 1.4848633e-3 6.4707125e-2" rpy="3.0686 -1.5089 1.6549"/>
        <mass value="0.154"/>
        <inertia ixx="9.2363919e-5" ixy="0.0" ixz="0.0" iyy="2.7365867e-4" iyz="0.0" izz="2.7990892e-4"/>
      </inertial>
    </link>

    <joint name="Joint_3_left" type="revolute">
      <axis xyz="1 0 0"/>
      <limit effort="1000.0" lower="0" upper="1.571" velocity="1"/>
      <parent link="Link_two_left"/>
      <child link="Link_three_left"/>
      <origin xyz="0 0 0.138"/>
      <dynamics damping="${damping}" friction="${friction}"/>

    </joint>


    <link name="Link_three_left">
      <visual>
        <origin rpy="0 0 0" xyz="0 0 24e-3"/>
        <geometry>
          <mesh filename="package://aerial_ego_simulation/meshes/arm/j3.stl" scale="0.001 0.001 0.001"/>
        </geometry>
      </visual>

      <collision>
        <origin xyz="0 0 75.1e-3" rpy="0 0 0"/>
        <geometry>
          <box size="41e-3 42.5e-3 150.2e-3"/>
        </geometry>
      </collision>

      <inertial>
        <origin xyz="1.0689991e-4 4.5539723e-3 8.0348105e-2" rpy="0.0503 -1.4936 -1.6299"/>
        <mass value="0.207"/>
        <inertia ixx="8.4188171e-5" ixy="0.0" ixz="0.0" iyy="3.4408597e-4" iyz="0.0" izz="3.6490830e-4"/>
      </inertial>
    </link>

    <joint name="Joint_wrist_left" type="revolute">
      <axis xyz="0 0 1"/>
      <limit effort="1000.0" lower="-3.14" upper="3.14" velocity="1"/>
      <parent link="Link_three_left"/>
      <child link="Link_hand_left"/>
      <origin xyz="0 0 0.1502" rpy="0 0 ${-pi/2}"/>
      <dynamics damping="${damping}" friction="${friction}"/>

    </joint>

    <link name="Link_hand_left">
      <visual>
        <origin rpy="0 0 0 " xyz="0 0 0"/>
        <geometry>
          <mesh filename="package://aerial_ego_simulation/meshes/arm/hand_left.stl" scale="0.001 0.001 0.001"/>
        </geometry>
      </visual>

      <collision>

        <surface>
          <friction>
            <ode>
              <mu>5</mu>
              <mu2>5</mu2>
              <kp value="10000000.0" />
              <kd value="1.0" />
            </ode>
          </friction>

          <!-- <soft_contact>
          <dart>
            <bone_attachment>100
            </bone_attachment>
            <stiffness>100
            </stiffness>
            <damping>10
            </damping>
          </dart>
        </soft_contact> -->

        </surface>



        <origin xyz="0 0 102.556e-3" rpy="0 0 0"/>
        <geometry>
          <box size="80e-3 36e-3 205.122e-3"/>
        </geometry>
      </collision>

      <inertial>
        <origin xyz="-5.1914952e-3 9.4338844e-4 8.4791871e-2" rpy="2.7807 -1.4896 1.8174"/>
        <mass value="0.505"/>
        <inertia ixx="3.2734333e-4" ixy="0.0" ixz="0.0" iyy="1.1324016e-3" iyz="0.0" izz="1.3591446e-3"/>
      </inertial>
    </link>

    <transmission name="tran0_right">
      <type>transmission_interface/SimpleTransmission</type>
      <joint name="Joint_shoulder_right">
        <hardwareInterface>hardware_interface/EffortJointInterface</hardwareInterface>
      </joint>
      <actuator name="motor0_right">
        <hardwareInterface>hardware_interface/EffortJointInterface</hardwareInterface>
        <mechanicalReduction>1</mechanicalReduction>
      </actuator>
    </transmission>

    <transmission name="tran1_right">
      <type>transmission_interface/SimpleTransmission</type>
      <joint name="Joint_1_right">
        <hardwareInterface>hardware_interface/EffortJointInterface</hardwareInterface>
      </joint>
      <actuator name="motor1_right">
        <hardwareInterface>hardware_interface/EffortJointInterface</hardwareInterface>
        <mechanicalReduction>1</mechanicalReduction>
      </actuator>
    </transmission>

    <transmission name="tran2_right">
      <type>transmission_interface/SimpleTransmission</type>
      <joint name="Joint_2_right">
        <hardwareInterface>hardware_interface/EffortJointInterface</hardwareInterface>
      </joint>
      <actuator name="motor2_right">
        <hardwareInterface>hardware_interface/EffortJointInterface</hardwareInterface>
        <mechanicalReduction>1</mechanicalReduction>
      </actuator>
    </transmission>

    <transmission name="tran3_right">
      <type>transmission_interface/SimpleTransmission</type>
      <joint name="Joint_3_right">
        <hardwareInterface>hardware_interface/EffortJointInterface</hardwareInterface>
      </joint>
      <actuator name="motor3_right">
        <hardwareInterface>hardware_interface/EffortJointInterface</hardwareInterface>
        <mechanicalReduction>1</mechanicalReduction>
      </actuator>
    </transmission>

    <transmission name="tran4_right">
      <type>transmission_interface/SimpleTransmission</type>
      <joint name="Joint_wrist_right">
        <hardwareInterface>hardware_interface/EffortJointInterface</hardwareInterface>
      </joint>
      <actuator name="motor4_right">
        <hardwareInterface>hardware_interface/EffortJointInterface</hardwareInterface>
        <mechanicalReduction>1</mechanicalReduction>
      </actuator>
    </transmission>

    <transmission name="tran0_left">
      <type>transmission_interface/SimpleTransmission</type>
      <joint name="Joint_shoulder_left">
        <hardwareInterface>hardware_interface/EffortJointInterface</hardwareInterface>
      </joint>
      <actuator name="motor0_left">
        <hardwareInterface>hardware_interface/EffortJointInterface</hardwareInterface>
        <mechanicalReduction>1</mechanicalReduction>
      </actuator>
    </transmission>

    <transmission name="tran1_left">
      <type>transmission_interface/SimpleTransmission</type>
      <joint name="Joint_1_left">
        <hardwareInterface>hardware_interface/EffortJointInterface</hardwareInterface>
      </joint>
      <actuator name="motor1_left">
        <hardwareInterface>hardware_interface/EffortJointInterface</hardwareInterface>
        <mechanicalReduction>1</mechanicalReduction>
      </actuator>
    </transmission>

    <transmission name="tran2_left">
      <type>transmission_interface/SimpleTransmission</type>
      <joint name="Joint_2_left">
        <hardwareInterface>hardware_interface/EffortJointInterface</hardwareInterface>
      </joint>
      <actuator name="motor2_left">
        <hardwareInterface>hardware_interface/EffortJointInterface</hardwareInterface>
        <mechanicalReduction>1</mechanicalReduction>
      </actuator>
    </transmission>

    <transmission name="tran3_left">
      <type>transmission_interface/SimpleTransmission</type>
      <joint name="Joint_3_left">
        <hardwareInterface>hardware_interface/EffortJointInterface</hardwareInterface>
      </joint>
      <actuator name="motor3_left">
        <hardwareInterface>hardware_interface/EffortJointInterface</hardwareInterface>
        <mechanicalReduction>1</mechanicalReduction>
      </actuator>
    </transmission>

    <transmission name="tran4_left">
      <type>transmission_interface/SimpleTransmission</type>
      <joint name="Joint_wrist_left">
        <hardwareInterface>hardware_interface/EffortJointInterface</hardwareInterface>
      </joint>
      <actuator name="motor4_left">
        <hardwareInterface>hardware_interface/EffortJointInterface</hardwareInterface>
        <mechanicalReduction>1</mechanicalReduction>
      </actuator>
    </transmission>

  </xacro:macro>
</robot>